Workbook

Sheet Student_Test
A1: Faculty of Information and Communication Technology
A2: Mahidol University
A3: English Proficiency Test Score for Graduation
A4: COVERAGE INFORMATION
Y5: Auto??? | AA5: Tum กรอก เมื่อจะนำเสนอเซ็น | AB5: Tum กรอกเมื่อได้ลายเซ็นแล้ว วันที่ตรงนี้จะนำไปใช้ส่งต่อให้มหาวิทยาลัย | AC5: Mail Merge ส่งเมล์เมื่อ Dean
A6: No. | B6: AcademicYear | C6: Graduate Year | D6: Program | E6: ID | F6: Title | G6: Firstname | H6: Lastname | I6: Type of Subtitute | J6: Score | K6: Listening | L6: Reading | M6: Writing | N6: Speaking | O6: Literacy | P6: Conversation | Q6: Comprehension | R6: Production | S6: Test Date | T6: Annouced date | U6: Type for TOEFL | V6: Client | W6: Tel no. | X6: Student Email | Y6: Approve Date | Z6: Certificate | AA6: รอบเสนอ Dean | AB6: Dean Approve Date | AC6: Notify to Student
A7: 1 | B7: =VALUE(LEFT(E7,2)) -> 63 | C7: =VALUE("25"&B7)-543+3 -> 2023 | D7: ICT | E7: 6388001 | F7: MR. | G7: Thanakorn | H7: Kannika | I7: Pass TOEFL | J7: 5000 | K7: 2580 | M7: 1300 | N7: 1200 | S7: 14882 | U7: CBT | X7: tanakorn.kan@mahidol.ac.th | Y7: 44441.663 | Z7: https://studentmahidolac.sharepoint.com/sites/AcademicTeam603/Shared%20Documents/%E0%B9%81%E0%B8%AD%E0%B8%9B/Microsoft%20Forms/English%20Proficiency%20Test%20for%20Graduation%20-%20English/Please%20attached%20the%20original%20score%20certificate/205729619_4214716881883610_207278601184615471_Thanakorn%20Kannika.jpg
A8: 2 | B8: =VALUE(LEFT(E8,2)) -> 63 | C8: =VALUE("25"&B8)-543+3 -> 2023 | D8: ICT | E8: 6388002 | F8: MISS | G8: Siriporn | H8: Rojanakosol | I8: Pass TOEIC | J8: 1650 | K8: 1660 | L8: 90 | S8: 44806 | V8: Asok | X8: =CONCATENATE(LOWER(G8),".",LOWER(LEFT(H8,3)),"@mahidol.ac.th") -> siriporn.roj@mahidol.ac.th | Y8: 44441.666 | Z8: https://studentmahidolac.sharepoint.com/sites/AcademicTeam603/Shared%20Documents/%E0%B9%81%E0%B8%AD%E0%B8%9B/Microsoft%20Forms/English%20Proficiency%20Test%20for%20Graduation%20-%20English/Please%20attached%20the%20original%20score%20certificate/EnglishText_Siriporn%20Rojanakosol.JPG
A9: 3 | B9: =VALUE(LEFT(E9,2)) -> 63 | C9: =VALUE("25"&B9)-543+3 -> 2023 | D9: ICT | E9: 6388003 | F9: MR. | G9: Pipatpong | H9: Niyommungmee | I9: Pass MUELT | X9: =CONCATENATE(LOWER(G9),".",LOWER(LEFT(H9,3)),"@mahidol.ac.th") -> pipatpong.niy@mahidol.ac.th
A10: 4 | B10: =VALUE(LEFT(E10,2)) -> 63 | C10: =VALUE("25"&B10)-543+3 -> 2023 | D10: ICT | E10: 6388004 | F10: MR. | G10: Karn | H10: Liamruk | I10: Pass MUELT | X10: =CONCATENATE(LOWER(G10),".",LOWER(LEFT(H10,3)),"@mahidol.ac.th") -> karn.lia@mahidol.ac.th
A11: 5 | B11: =VALUE(LEFT(E11,2)) -> 61 | C11: =VALUE("25"&B11)-543+3 -> 2021 | D11: ICT | E11: 6188005 | F11: MISS | G11: Siripen | H11: Pongpaichet | I11: Pass MUELT | J11: 100 | K11: 50 | L11: 50 | S11: 44440 | X11: =CONCATENATE(LOWER(G11),".",LOWER(LEFT(H11,3)),"@mahidol.ac.th") -> siripen.pon@mahidol.ac.th | Y11: 44445.443 | Z11: https://studentmahidolac.sharepoint.com/sites/AcademicTeam603/Shared%20Documents/%E0%B9%81%E0%B8%AD%E0%B8%9B/Microsoft%20Forms/English%20Proficiency%20Test%20for%20Graduation%20-%20English/Please%20attached%20the%20original%20score%20certificate/MUICT3_SIRIPEN%20PONGPAICHET.png
A12: 6 | B12: =VALUE(LEFT(E12,2)) -> 61 | C12: =VALUE("25"&B12)-543+3 -> 2021 | D12: ICT | E12: 6188006 | F12: MISS | G12: Woramon | H12: Chareonsuk | I12: Pass MUELT | J12: 150 | K12: 75 | L12: 75 | S12: 44445 | X12: =CONCATENATE(LOWER(G12),".",LOWER(LEFT(H12,3)),"@mahidol.ac.th") -> woramon.cha@mahidol.ac.th | Y12: 44454.546 | Z12: https://studentmahidolac.sharepoint.com/sites/AcademicTeam603/Shared%20Documents/%E0%B9%81%E0%B8%AD%E0%B8%9B/Microsoft%20Forms/English%20Proficiency%20Test%20for%20Graduation%20-%20English/Please%20attached%20the%20original%20score%20certificate/MUICT2_Woramon%20Chareonsuk%208.png
A13: 7 | B13: =VALUE(LEFT(E13,2)) -> 61 | C13: =VALUE("25"&B13)-543+3 -> 2021 | D13: ICT | E13: 6188007 | F13: MR. | G13: Patipat | H13: Chewprecha | I13: Not Pass | J13: 700 | K13: 400 | L13: 300 | S13: 44440 | V13: MU | X13: =CONCATENATE(LOWER(G13),".",LOWER(LEFT(H13,3)),"@mahidol.ac.th") -> patipat.che@mahidol.ac.th | Y13: 44452.691 | Z13: https://studentmahidolac.sharepoint.com/sites/AcademicTeam603/Shared%20Documents/%E0%B9%81%E0%B8%AD%E0%B8%9B/Microsoft%20Forms/English%20Proficiency%20Test%20for%20Graduation%20-%20English/Please%20attached%20the%20original%20score%20certificate/IDCardExample_Patipat%20Chewprecha%2010.jpg
A14: 8 | B14: =VALUE(LEFT(E14,2)) -> 60 | C14: =VALUE("25"&B14)-543+3 -> 2020 | D14: ICT | E14: 6088008 | F14: MR. | G14: Poobase | H14: Somanawat | I14: Pass TOEIC | J14: 800 | K14: 400 | L14: 400 | S14: 44440 | V14: MU | X14: =CONCATENATE(LOWER(G14),".",LOWER(LEFT(H14,3)),"@mahidol.ac.th") -> poobase.som@mahidol.ac.th
A15: 9 | B15: =VALUE(LEFT(E15,2)) -> 63 | C15: =VALUE("25"&B15)-543+3 -> 2023 | D15: ICT | E15: 6388009 | F15: MISS | G15: Saengduean | H15: Pornpanomchai | I15: Pass TOEIC | J15: 800 | K15: 400 | L15: 400 | S15: 44440 | V15: MU | X15: =CONCATENATE(LOWER(G15),".",LOWER(LEFT(H15,3)),"@mahidol.ac.th") -> saengduean.por@mahidol.ac.th
A16: 10 | B16: =VALUE(LEFT(E16,2)) -> 63 | C16: =VALUE("25"&B16)-543+3 -> 2023 | D16: ICT | E16: 6388010 | F16: MISS | G16: Warunthorn | H16: Jeansamoot | I16: Pass MUELT
A17: 11 | B17: =VALUE(LEFT(E17,2)) -> 63 | C17: =VALUE("25"&B17)-543+3 -> 2023 | D17: ICT | E17: 6388011 | F17: MISS | G17: Sudarat | H17: Chutilimpachart | I17: Pass MUELT | X17: sudarat.nan@mahidol.ac.th
A18: 12 | B18: =VALUE(LEFT(E18,2)) -> 63 | C18: =VALUE("25"&B18)-543+3 -> 2023 | D18: ICT | E18: 6388012 | F18: MR. | G18: Supakorn | H18: Panpithak | I18: Pass MUELT | J18: 7 | K18: 7 | L18: 7 | M18: 7 | N18: 7 | S18: 44448 | X18: supakorn.pap@mahidol.ac.th | Y18: 44448.554 | Z18: https://studentmahidolac.sharepoint.com/sites/AcademicTeam603/Shared%20Documents/%E0%B9%81%E0%B8%AD%E0%B8%9B/Microsoft%20Forms/English%20Proficiency%20Test%20for%20Graduation%20-%20English/Please%20attached%20the%20original%20score%20certificate/190153213_267017145213647_6747098700929083546_Supakorn%20Panpithak.jpg
A19: 13 | B19: =VALUE(LEFT(E19,2)) -> 63 | C19: =VALUE("25"&B19)-543+3 -> 2023 | D19: ICT | E19: 6388013 | F19: MR. | G19: Itthiphol | H19: Makkappalanon | I19: Pass MUELT | X19: =CONCATENATE(LOWER(G19),".",LOWER(LEFT(H19,3)),"@mahidol.ac.th") -> itthiphol.mak@mahidol.ac.th
A20: 14 | B20: =VALUE(LEFT(E20,2)) -> 63 | C20: =VALUE("25"&B20)-543+3 -> 2023 | D20: ICT | E20: 6388014 | F20: MR. | G20: Alexander | H20: Salde | I20: Pass MUELT | J20: 600 | K20: 200 | M20: 200 | N20: 200 | S20: 44427 | U20: PBT | X20: =CONCATENATE(LOWER(G20),".",LOWER(LEFT(H20,3)),"@mahidol.ac.th") -> alexander.sal@mahidol.ac.th | Y20: 44441.676 | Z20: https://studentmahidolac.sharepoint.com/sites/AcademicTeam603/Shared%20Documents/%E0%B9%81%E0%B8%AD%E0%B8%9B/Microsoft%20Forms/English%20Proficiency%20Test%20for%20Graduation%20-%20English/Please%20attached%20the%20original%20score%20certificate/toefl%20(1)_Alexander%20Salde.jpg
A21: 16 | B21: =VALUE(LEFT(E21,2)) -> 62 | C21: =VALUE("25"&B21)-543+3 -> 2022 | D21: ICT | E21: 6288016 | F21: MISS | G21: Noppawan | H21: Raluekmool | I21: Pass MUELT | X21: =CONCATENATE(LOWER(G21),".",LOWER(LEFT(H21,3)),"@mahidol.ac.th") -> noppawan.ral@mahidol.ac.th
A22: 17 | B22: =VALUE(LEFT(E22,2)) -> 63 | C22: =VALUE("25"&B22)-543+3 -> 2023 | D22: ICT | E22: 6388017 | F22: MR. | G22: Prach | H22: Chaisiri | I22: Pass MUELT | X22: =CONCATENATE(LOWER(G22),".",LOWER(LEFT(H22,3)),"@mahidol.ac.th") -> prach.cha@mahidol.ac.th
A23: 18 | B23: =VALUE(LEFT(E23,2)) -> 61 | C23: =VALUE("25"&B23)-543+3 -> 2021 | D23: ICT | E23: 6188018 | F23: MISS | G23: Kullaporn | H23: Hongthong | I23: Pass MUELT | X23: =CONCATENATE(LOWER(G23),".",LOWER(LEFT(H23,3)),"@mahidol.ac.th") -> kullaporn.hon@mahidol.ac.th
A24: 19 | B24: =VALUE(LEFT(E24,2)) -> 61 | C24: =VALUE("25"&B24)-543+3 -> 2021 | D24: ICT | E24: 6188019 | F24: MISS | G24: Buntida | H24: Suvacharakulton | I24: Pass MUELT | X24: =CONCATENATE(LOWER(G24),".",LOWER(LEFT(H24,3)),"@mahidol.ac.th") -> buntida.suv@mahidol.ac.th
A25: 20 | B25: =VALUE(LEFT(E25,2)) -> 61 | C25: =VALUE("25"&B25)-543+3 -> 2021 | D25: ICT | E25: 6188020 | F25: MR. | G25: Jira | H25: Hutaman | I25: Pass MUELT | X25: =CONCATENATE(LOWER(G25),".",LOWER(LEFT(H25,3)),"@mahidol.ac.th") -> jira.hut@mahidol.ac.th
A26: 21 | B26: =VALUE(LEFT(E26,2)) -> 61 | C26: =VALUE("25"&B26)-543+3 -> 2021 | D26: ICT | E26: 6188021 | F26: MISS | G26: Kessarin | H26: Thoithat | I26: Pass MUELT | X26: kessrin.tho@mahidol.ac.th

Sheet Student_ICT
A1: Faculty of Information and Communication Technology
A2: Mahidol University
A3: English Proficiency Test Score for Graduation
A4: COVERAGE INFORMATION
AA5: Tum กรอก เมื่อจะนำเสนอเซ็น | AB5: Tum กรอกเมื่อได้ลายเซ็นแล้ว วันที่ตรงนี้จะนำไปใช้ส่งต่อให้มหาวิทยาลัย
A6: No. | B6: AcademicYear | C6: Graduate Year | D6: Program | E6: ID | F6: Title | G6: Firstname | H6: Lastname | I6: Type of Subtitute | J6: Score | K6: Listening | L6: Reading | M6: Writing | N6: Speaking | O6: Literacy | P6: Conversation | Q6: Comprehension | R6: Production | S6: Test Date | T6: Annouced date | U6: Type for TOEFL | V6: Client | W6: Tel no. | X6: Student Email | Y6: Approve Date | Z6: Certificate | AA6: รอบเสนอ Dean | AB6: Dean Approve Date | AC6: _ForSystem_StudentEmailNoSpace
A7: 1 | B7: =VALUE(LEFT(E7,2)) -> 58 | C7: =VALUE("25"&B7)-543+3 -> 2018 | E7: 5888012 | F7: MR. | G7: PUTTHICHAI | H7: CHAITHUMMAPAKORN | I7: Pass MU Intensive | J7: 76 | T7: 44531 | W7: 091-892-6259 | X7: putthichai.cha@student.mahidol.edu | AC7: =TRIM(StudentScore[[#This Row],[Student Email]]) -> putthichai.cha@student.mahidol.edu
A8: 2 | B8: =VALUE(LEFT(E8,2)) -> 59 | C8: =VALUE("25"&B8)-543+3 -> 2019 | E8: 5988181 | F8: MR. | G8: WARINTORN | H8: VISEDSANG | I8: Not Pass | W8: 088-610-8826 | X8: warintorn.vis@student.mahidol.ac.th | AC8: =TRIM(StudentScore[[#This Row],[Student Email]]) -> warintorn.vis@student.mahidol.ac.th
A9: 3 | B9: =VALUE(LEFT(E9,2)) -> 59 | C9: =VALUE("25"&B9)-543+3 -> 2019 | E9: 5988259 | F9: MR. | G9: RAPIPAT | H9: UDOMGUN | I9: Not Pass | W9: 097-169-1665 | X9: rapipat.udo@student.mahidol.ac.th | AC9: =TRIM(StudentScore[[#This Row],[Student Email]]) -> rapipat.udo@student.mahidol.ac.th
A10: 4 | B10: =VALUE(LEFT(E10,2)) -> 60 | C10: =VALUE("25"&B10)-543+3 -> 2020 | E10: 6088228 | F10: MR. | G10: VARUIT | H10: WUTTISATHIT | I10: Pass MU Intensive | J10: 76 | T10: 44682 | W10: 081-845-5023 | X10: varuit.wui@student.mahidol.ac.th | AC10: =TRIM(StudentScore[[#This Row],[Student Email]]) -> varuit.wui@student.mahidol.ac.th
A11: 5 | B11: =VALUE(LEFT(E11,2)) -> 61 | C11: =VALUE("25"&B11)-543+3 -> 2021 | E11: 6188001 | F11: MISS | G11: VIDCHAYADA | H11: CHAISANGKHA | I11: Pass TOEFL | J11: 543 | K11: 57 | L11: 50 | M11: 56 | S11: 44347 | T11: 44348 | W11: 081-406-1002 | X11: vidchayada.cha@student.mahidol.ac.th | AC11: =TRIM(StudentScore[[#This Row],[Student Email]]) -> vidchayada.cha@student.mahidol.ac.th
A12: 6 | B12: =VALUE(LEFT(E12,2)) -> 61 | C12: =VALUE("25"&B12)-543+3 -> 2021 | E12: 6188002 | F12: MISS | G12: RAMITA | H12: CHONGCHAM | I12: Pass IELTS | J12: 5.5 | K12: 5.5 | L12: 6 | M12: 5.5 | N12: 5 | S12: 43574 | T12: 43556 | W12: 092-520-4430 | X12: ramita.cho@student.mahidol.ac.th | AC12: =TRIM(StudentScore[[#This Row],[Student Email]]) -> ramita.cho@student.mahidol.ac.th
A13: 7 | B13: =VALUE(LEFT(E13,2)) -> 61 | C13: =VALUE("25"&B13)-543+3 -> 2021 | E13: 6188003 | F13: MISS | G13: AORAVEE | H13: DONNOMPRI | I13: Pass TOEIC | J13: 670 | K13: 370 | L13: 300 | S13: 43880 | T13: 43862 | W13: 095-887-1177 | X13: aoravee.don@student.mahidol.ac.th | AC13: =TRIM(StudentScore[[#This Row],[Student Email]]) -> aoravee.don@student.mahidol.ac.th
A14: 8 | B14: =VALUE(LEFT(E14,2)) -> 61 | C14: =VALUE("25"&B14)-543+3 -> 2021 | E14: 6188005 | F14: MISS | G14: VARISARA | H14: JANMATAKULWAT | I14: Pass Duolingo | J14: 100 | S14: 44355 | T14: 44348 | W14: 092-250-3183 | X14: varisara.jan@student.mahidol.ac.th | AC14: =TRIM(StudentScore[[#This Row],[Student Email]]) -> varisara.jan@student.mahidol.ac.th
A15: 9 | B15: =VALUE(LEFT(E15,2)) -> 61 | C15: =VALUE("25"&B15)-543+3 -> 2021 | E15: 6188006 | F15: MR. | G15: JIRAKORN | H15: JIRAPONPAISAL | I15: Pass IELTS | J15: 6.5 | K15: 7 | L15: 6.5 | M15: 5.5 | N15: 6 | S15: 42833 | T15: 43313 | W15: 085-555-3449 | X15: jirakorn.jir@student.mahidol.ac.th | AC15: =TRIM(StudentScore[[#This Row],[Student Email]]) -> jirakorn.jir@student.mahidol.ac.th
A16: 10 | B16: =VALUE(LEFT(E16,2)) -> 61 | C16: =VALUE("25"&B16)-543+3 -> 2021 | E16: 6188007 | F16: MR. | G16: WORAWIT | H16: KAEWPRASERT | I16: Pass TOEIC | J16: 790 | K16: 425 | L16: 365 | S16: 44090 | T16: 44105 | W16: 090-101-9395 | X16: worawit.kae@student.mahidol.ac.th | AC16: =TRIM(StudentScore[[#This Row],[Student Email]]) -> worawit.kae@student.mahidol.ac.th
A17: 11 | B17: =VALUE(LEFT(E17,2)) -> 61 | C17: =VALUE("25"&B17)-543+3 -> 2021 | E17: 6188008 | F17: MISS | G17: NATTHAPORN | H17: KOBKULKALYAKORN | I17: Pass TOEIC | J17: 650 | K17: 310 | L17: 340 | S17: 43880 | T17: 43862 | W17: 092-248-3162 | X17: natthaporn.kob@student.mahidol.ac.th | AC17: =TRIM(StudentScore[[#This Row],[Student Email]]) -> natthaporn.kob@student.mahidol.ac.th
A18: 12 | B18: =VALUE(LEFT(E18,2)) -> 61 | C18: =VALUE("25"&B18)-543+3 -> 2021 | E18: 6188009 | F18: MR. | G18: PHUMRAPEE | H18: LIMPIANCHOP | I18: Pass TOEIC | J18: 865 | K18: 455 | L18: 410 | S18: 44153 | T18: 44136 | W18: 088-658-2601 | X18: phumrapee.lim@student.mahidol.ac.th | AC18: =TRIM(StudentScore[[#This Row],[Student Email]]) -> phumrapee.lim@student.mahidol.ac.th
A19: 13 | B19: =VALUE(LEFT(E19,2)) -> 61 | C19: =VALUE("25"&B19)-543+3 -> 2021 | E19: 6188010 | F19: MISS | G19: CHANSIDA | H19: MAKARANOND | I19: Pass IELTS | J19: 7 | K19: 8 | L19: 7.5 | M19: 6 | N19: 6 | S19: 42959 | T19: 43313 | W19: 081-900-5885 | X19: chansida.mak@student.mahidol.ac.th | AC19: =TRIM(StudentScore[[#This Row],[Student Email]]) -> chansida.mak@student.mahidol.ac.th
A20: 14 | B20: =VALUE(LEFT(E20,2)) -> 61 | C20: =VALUE("25"&B20)-543+3 -> 2021 | E20: 6188011 | F20: MISS | G20: OSH | H20: NARAYAN | I20: Pass IELTS | J20: 6.5 | K20: 6.5 | L20: 5 | M20: 6 | N20: 8 | S20: 42987 | T20: 43313 | W20: 092-256-6571 | X20: osh.nar@student.mahidol.ac.th | AC20: =TRIM(StudentScore[[#This Row],[Student Email]]) -> osh.nar@student.mahidol.ac.th
A21: 15 | B21: =VALUE(LEFT(E21,2)) -> 61 | C21: =VALUE("25"&B21)-543+3 -> 2021 | E21: 6188012 | F21: MR. | G21: SUTTIPAT | H21: BURANATREVEDH | I21: Pass TOEIC | J21: 650 | K21: 410 | L21: 240 | S21: 43903 | T21: 44044 | W21: 085-252-8447 | X21: suttipat.bur@student.mahidol.ac.th | AC21: =TRIM(StudentScore[[#This Row],[Student Email]]) -> suttipat.bur@student.mahidol.ac.th
A22: 16 | B22: =VALUE(LEFT(E22,2)) -> 61 | C22: =VALUE("25"&B22)-543+3 -> 2021 | E22: 6188013 | F22: MR. | G22: ANAKIN | H22: PATCHAROTHAI | I22: Pass TOEIC | J22: 850 | K22: 435 | L22: 415 | S22: 43880 | T22: 43862 | W22: 089-019-9919 | X22: anakin.pat@student.mahidol.ac.th | AC22: =TRIM(StudentScore[[#This Row],[Student Email]]) -> anakin.pat@student.mahidol.ac.th
A23: 17 | B23: =VALUE(LEFT(E23,2)) -> 61 | C23: =VALUE("25"&B23)-543+3 -> 2021 | E23: 6188014 | F23: MR. | G23: SUTTICHOK | H23: CHOTISAKUL | I23: Pass TOEIC | J23: 820 | K23: 470 | L23: 350 | S23: 43880 | T23: 43862 | W23: 086-661-2188 | X23: suttichok.cho@student.mahidol.ac.th | AC23: =TRIM(StudentScore[[#This Row],[Student Email]]) -> suttichok.cho@student.mahidol.ac.th
A24: 18 | B24: =VALUE(LEFT(E24,2)) -> 61 | C24: =VALUE("25"&B24)-543+3 -> 2021 | E24: 6188015 | F24: MR. | G24: WEERAPAT | H24: PIPITHRUENGKRAI | I24: Pass TOEIC | J24: 800 | K24: 380 | L24: 420 | S24: 43880 | T24: 43862 | W24: 093-134-2998 | X24: weerapat.pip@student.mahidol.ac.th | AC24: =TRIM(StudentScore[[#This Row],[Student Email]]) -> weerapat.pip@student.mahidol.ac.th
A25: 19 | B25: =VALUE(LEFT(E25,2)) -> 61 | C25: =VALUE("25"&B25)-543+3 -> 2021 | E25: 6188016 | F25: MISS | G25: THANAPORN | H25: PLANGPHATTHANAPHANIT | I25: Pass TOEIC | J25: 715 | K25: 350 | L25: 365 | S25: 43880 | T25: 43862 | W25: 061-436-4199 | X25: thanaporn.pln@student.mahidol.ac.th | AC25: =TRIM(StudentScore[[#This Row],[Student Email]]) -> thanaporn.pln@student.mahidol.ac.th
A26: 20 | B26: =VALUE(LEFT(E26,2)) -> 61 | C26: =VALUE("25"&B26)-543+3 -> 2021 | E26: 6188018 | F26: MR. | G26: PATTARAKRIT | H26: RATTANUKUL | I26: Pass IELTS | J26: 6 | K26: 6 | L26: 6.5 | M26: 5.5 | N26: 5.5 | S26: 42973 | T26: 43313 | W26: 085-529-2495 | X26: pattarakrit.rat@student.mahidol.ac.th | AC26: =TRIM(StudentScore[[#This Row],[Student Email]]) -> pattarakrit.rat@student.mahidol.ac.th
A27: 21 | B27: =VALUE(LEFT(E27,2)) -> 61 | C27: =VALUE("25"&B27)-543+3 -> 2021 | E27: 6188019 | F27: MR. | G27: THANAWAT | H27: RIAMLIW | I27: Pass MU Intensive | J27: 88 | T27: 44348 | W27: 098-046-9960 | X27: thanawat.ria@student.mahidol.ac.th | AC27: =TRIM(StudentScore[[#This Row],[Student Email]]) -> thanawat.ria@student.mahidol.ac.th
A28: 22 | B28: =VALUE(LEFT(E28,2)) -> 61 | C28: =VALUE("25"&B28)-543+3 -> 2021 | E28: 6188020 | F28: MR. | G28: CHANATHIP | H28: SIRISANGPAIVAL | I28: Pass MU Intensive | J28: 85 | T28: 44682 | W28: 089-490-0698 | X28: chanathip.sir@student.mahidol.ac.th | AC28: =TRIM(StudentScore[[#This Row],[Student Email]]) -> chanathip.sir@student.mahidol.ac.th
A29: 23 | B29: =VALUE(LEFT(E29,2)) -> 61 | C29: =VALUE("25"&B29)-543+3 -> 2021 | E29: 6188021 | F29: MR. | G29: RUKSAT | H29: SOLADDA | I29: Pass MU Intensive | J29: 77 | T29: 44531 | W29: 091-738-7893 | X29: ruksat.sol@student.mahidol.ac.th | AC29: =TRIM(StudentScore[[#This Row],[Student Email]]) -> ruksat.sol@student.mahidol.ac.th
A30: 24 | B30: =VALUE(LEFT(E30,2)) -> 61 | C30: =VALUE("25"&B30)-543+3 -> 2021 | E30: 6188022 | F30: MR. | G30: WEERAPHAT | H30: SRISUTHAM | I30: Pass MU Intensive | J30: 76 | T30: 44348 | W30: 086-889-1068 | X30: weeraphat.sri@student.mahidol.ac.th | AC30: =TRIM(StudentScore[[#This Row],[Student Email]]) -> weeraphat.sri@student.mahidol.ac.th
A31: 25 | B31: =VALUE(LEFT(E31,2)) -> 61 | C31: =VALUE("25"&B31)-543+3 -> 2021 | E31: 6188023 | F31: MISS | G31: PRAEWNAPA | H31: SUKHARANGSAN | I31: Pass TOEIC | J31: 620 | K31: 330 | L31: 290 | S31: 44090 | T31: 44075 | W31: 087-669-4207 | X31: praewnapa.suk@student.mahidol.ac.th | AC31: =TRIM(StudentScore[[#This Row],[Student Email]]) -> praewnapa.suk@student.mahidol.ac.th
A32: 26 | B32: =VALUE(LEFT(E32,2)) -> 61 | C32: =VALUE("25"&B32)-543+3 -> 2021 | E32: 6188024 | F32: MISS | G32: SUMUNA | H32: THAIJIA | I32: Pass MU Intensive | J32: 77 | T32: 44531 | W32: 084-864-9426 | X32: sumuna.tha@student.mahidol.ac.th | AC32: =TRIM(StudentScore[[#This Row],[Student Email]]) -> sumuna.tha@student.mahidol.ac.th
A33: 27 | B33: =VALUE(LEFT(E33,2)) -> 61 | C33: =VALUE("25"&B33)-543+3 -> 2021 | E33: 6188025 | F33: MISS | G33: ALISA | H33: UTHIKAMPORN | I33: Pass TOEIC | J33: 655 | K33: 345 | L33: 310 | S33: 43334 | T33: 43374 | W33: 080-448-8048 | X33: alisa.uth@student.mahidol.ac.th | AC33: =TRIM(StudentScore[[#This Row],[Student Email]]) -> alisa.uth@student.mahidol.ac.th
A34: 28 | B34: =VALUE(LEFT(E34,2)) -> 61 | C34: =VALUE("25"&B34)-543+3 -> 2021 | E34: 6188026 | F34: MR. | G34: PUMIPAT | H34: WATANAKULCHARUS | I34: Pass DUOLINGO | J34: 120 | O34: 120 | P34: 95 | Q34: 135 | R34: 75 | S34: 44680 | T34: 44683 | W34: 082-348-2305 | X34: pumipat.wat@student.mahidol.ac.th | Y34: 44683.89 | Z34: https://studentmahidolac.sharepoint.com/sites/AcademicTeam603/Shared%20Documents/%E0%B9%81%E0%B8%AD%E0%B8%9B/Microsoft%20Forms/English%20Proficiency%20Test%20for%20Graduation%20-%20English/Please%20attached%20the%20original%20score%20certificate/Duolingo%20English%20Test_PUMIPAT%20WATANAKULCHA.pdf | AC34: =TRIM(StudentScore[[#This Row],[Student Email]]) -> pumipat.wat@student.mahidol.ac.th
A35: 29 | B35: =VALUE(LEFT(E35,2)) -> 61 | C35: =VALUE("25"&B35)-543+3 -> 2021 | E35: 6188027 | F35: MISS | G35: SUPAKAN | H35: YODRUANGSA | I35: Pass TOEIC | J35: 820 | K35: 420 | L35: 400 | S35: 43880 | T35: 43862 | W35: 087-776-0028 | X35: supakan.yod@student.mahidol.ac.th | AC35: =TRIM(StudentScore[[#This Row],[Student Email]]) -> supakan.yod@student.mahidol.ac.th
A36: 30 | B36: =VALUE(LEFT(E36,2)) -> 61 | C36: =VALUE("25"&B36)-543+3 -> 2021 | E36: 6188028 | F36: MR. | G36: NATAKORN | H36: HONGHAN | I36: Pass MU Intensive | J36: 85 | T36: 44531 | W36: 088-095-0014 | X36: natakorn.hon@student.mahidol.ac.th | AC36: =TRIM(StudentScore[[#This Row],[Student Email]]) -> natakorn.hon@student.mahidol.ac.th
A37: 31 | B37: =VALUE(LEFT(E37,2)) -> 61 | C37: =VALUE("25"&B37)-543+3 -> 2021 | E37: 6188029 | F37: MR. | G37: NAPHAT | H37: KHAJOHN-UDOMRITH | I37: Pass MU Intensive | J37: 81 | T37: 44348 | W37: 095-947-4543 | X37: naphat.kha@student.mahidol.ac.th | AC37: =TRIM(StudentScore[[#This Row],[Student Email]]) -> naphat.kha@student.mahidol.ac.th
A38: 32 | B38: =VALUE(LEFT(E38,2)) -> 61 | C38: =VALUE("25"&B38)-543+3 -> 2021 | E38: 6188030 | F38: MR. | G38: RATTANUNT | H38: KUMPEERASART | I38: Pass MU Intensive | J38: 79 | T38: 44531 | W38: 083-854-2788 | X38: rattanunt.kum@student.mahidol.ac.th | AC38: =TRIM(StudentScore[[#This Row],[Student Email]]) -> rattanunt.kum@student.mahidol.ac.th
A39: 33 | B39: =VALUE(LEFT(E39,2)) -> 61 | C39: =VALUE("25"&B39)-543+3 -> 2021 | E39: 6188031 | F39: MISS | G39: THANYARAT | H39: KUNARITTIPOL | I39: Pass Duolingo | J39: 100 | O39: 95 | P39: 95 | Q39: 105 | R39: 85 | S39: 44585 | T39: 44631 | W39: 087-488-2263 | X39: thanyarat.kun@student.mahidol.ac.th | AC39: =TRIM(StudentScore[[#This Row],[Student Email]]) -> thanyarat.kun@student.mahidol.ac.th
A40: 34 | B40: =VALUE(LEFT(E40,2)) -> 61 | C40: =VALUE("25"&B40)-543+3 -> 2021 | E40: 6188033 | F40: MISS | G40: NUTTIDA | H40: NAPAKAS | I40: Pass MU Intensive | J40: 77 | T40: 44348 | W40: 061-013-1064 | X40: nuttida.nap@student.mahidol.ac.th | AC40: =TRIM(StudentScore[[#This Row],[Student Email]]) -> nuttida.nap@student.mahidol.ac.th
...

Sheet Subtitute
A1: Title | B1: ShowinReport
A2: Pass TOEIC | B2: 1
A3: Pass TOEFL | B3: 1
A4: Pass IELTS | B4: 1
A5: Pass MUELT | B5: 1
A6: Pass Duolingo | B6: 1
A7: Resign | B7: 0
A8: Not Pass | B8: 1
A9: Pass MU Intensive | B9: 1

Sheet Summary
A1: Table Summary Score : For Student | E1: Table Summary Score : For Administrator
A2: StdYear | B2: Category | C2: Value | E2: StdYear | F2: Category | G2: Program | H2: Value
A3: 60 | B3: Pass TOEIC | C3: =COUNTIFS(Student_ICT!I:I,Summary!$B3,Student_ICT!$B:$B,Summary!$A3) -> 0 | E3: 60 | F3: Pass TOEIC | G3: ICT | H3: =COUNTIFS(Student_ICT!$I:$I,Summary!$F3,Student_ICT!$B:$B,Summary!$E3,Student_ICT!$D:$D,Summary!$G3) -> 0
A4: 60 | B4: Pass TOEFL | C4: =COUNTIFS(Student_ICT!I:I,Summary!$B4,Student_ICT!$B:$B,Summary!$A4) -> 0 | E4: 60 | F4: Pass TOEFL | G4: ICT | H4: =COUNTIFS(Student_ICT!$I:$I,Summary!$F4,Student_ICT!$B:$B,Summary!$E4,Student_ICT!$D:$D,Summary!$G4) -> 0
A5: 60 | B5: Pass IELTS | C5: =COUNTIFS(Student_ICT!I:I,Summary!$B5,Student_ICT!$B:$B,Summary!$A5) -> 0 | E5: 60 | F5: Pass IELTS | G5: ICT | H5: =COUNTIFS(Student_ICT!$I:$I,Summary!$F5,Student_ICT!$B:$B,Summary!$E5,Student_ICT!$D:$D,Summary!$G5) -> 0
A6: 60 | B6: Pass MUELT | C6: =COUNTIFS(Student_ICT!I:I,Summary!$B6,Student_ICT!$B:$B,Summary!$A6) -> 0 | E6: 60 | F6: Pass MUELT | G6: ICT | H6: =COUNTIFS(Student_ICT!$I:$I,Summary!$F6,Student_ICT!$B:$B,Summary!$E6,Student_ICT!$D:$D,Summary!$G6) -> 0
A7: 60 | B7: Pass Duolingo | C7: =COUNTIFS(Student_ICT!I:I,Summary!$B7,Student_ICT!$B:$B,Summary!$A7) -> 0 | E7: 60 | F7: Pass Duolingo | G7: ICT | H7: =COUNTIFS(Student_ICT!$I:$I,Summary!$F7,Student_ICT!$B:$B,Summary!$E7,Student_ICT!$D:$D,Summary!$G7) -> 0
A8: 60 | B8: Not Pass | C8: =COUNTIFS(Student_ICT!I:I,Summary!$B8,Student_ICT!$B:$B,Summary!$A8) -> 0 | E8: 60 | F8: Not Pass | G8: ICT | H8: =COUNTIFS(Student_ICT!$I:$I,Summary!$F8,Student_ICT!$B:$B,Summary!$E8,Student_ICT!$D:$D,Summary!$G8) -> 0
A9: 61 | B9: Pass TOEIC | C9: =COUNTIFS(Student_ICT!I:I,Summary!$B9,Student_ICT!$B:$B,Summary!$A9) -> 36 | E9: 60 | F9: Resign | G9: ICT | H9: =COUNTIFS(Student_ICT!$I:$I,Summary!$F9,Student_ICT!$B:$B,Summary!$E9,Student_ICT!$D:$D,Summary!$G9) -> 0
A10: 61 | B10: Pass TOEFL | C10: =COUNTIFS(Student_ICT!I:I,Summary!$B10,Student_ICT!$B:$B,Summary!$A10) -> 4 | E10: 60 | F10: Pass TOEIC | G10: DST | H10: =COUNTIFS(Student_ICT!$I:$I,Summary!$F10,Student_ICT!$B:$B,Summary!$E10,Student_ICT!$D:$D,Summary!$G10) -> 0
A11: 61 | B11: Pass IELTS | C11: =COUNTIFS(Student_ICT!I:I,Summary!$B11,Student_ICT!$B:$B,Summary!$A11) -> 13 | E11: 60 | F11: Pass TOEFL | G11: DST | H11: =COUNTIFS(Student_ICT!$I:$I,Summary!$F11,Student_ICT!$B:$B,Summary!$E11,Student_ICT!$D:$D,Summary!$G11) -> 0
A12: 61 | B12: Pass MUELT | C12: =COUNTIFS(Student_ICT!I:I,Summary!$B12,Student_ICT!$B:$B,Summary!$A12) -> 0 | E12: 60 | F12: Pass IELTS | G12: DST | H12: =COUNTIFS(Student_ICT!$I:$I,Summary!$F12,Student_ICT!$B:$B,Summary!$E12,Student_ICT!$D:$D,Summary!$G12) -> 0
A13: 61 | B13: Pass Duolingo | C13: =COUNTIFS(Student_ICT!I:I,Summary!$B13,Student_ICT!$B:$B,Summary!$A13) -> 7 | E13: 60 | F13: Pass MUELT | G13: DST | H13: =COUNTIFS(Student_ICT!$I:$I,Summary!$F13,Student_ICT!$B:$B,Summary!$E13,Student_ICT!$D:$D,Summary!$G13) -> 0
A14: 61 | B14: Not Pass | C14: =COUNTIFS(Student_ICT!I:I,Summary!$B14,Student_ICT!$B:$B,Summary!$A14) -> 4 | E14: 60 | F14: Pass Duolingo | G14: DST | H14: =COUNTIFS(Student_ICT!$I:$I,Summary!$F14,Student_ICT!$B:$B,Summary!$E14,Student_ICT!$D:$D,Summary!$G14) -> 0
... A32: 64 | B32: Not Pass | C32: =COUNTIFS(Student_ICT!I:I,Summary!$B32,Student_ICT!$B:$B,Summary!$A32) -> 116 | E32: 61 | F32: Resign | G32: DST | H32: =COUNTIFS(Student_ICT!$I:$I,Summary!$F32,Student_ICT!$B:$B,Summary!$E32,Student_ICT!$D:$D,Summary!$G32) -> 0
E33: 62 | F33: Pass TOEIC | G33: ICT | H33: =COUNTIFS(Student_ICT!$I:$I,Summary!$F33,Student_ICT!$B:$B,Summary!$E33,Student_ICT!$D:$D,Summary!$G33) -> 0
E34: 62 | F34: Pass TOEFL | G34: ICT | H34: =COUNTIFS(Student_ICT!$I:$I,Summary!$F34,Student_ICT!$B:$B,Summary!$E34,Student_ICT!$D:$D,Summary!$G34) -> 0
E35: 62 | F35: Pass IELTS | G35: ICT | H35: =COUNTIFS(Student_ICT!$I:$I,Summary!$F35,Student_ICT!$B:$B,Summary!$E35,Student_ICT!$D:$D,Summary!$G35) -> 0
E36: 62 | F36: Pass MUELT | G36: ICT | H36: =COUNTIFS(Student_ICT!$I:$I,Summary!$F36,Student_ICT!$B:$B,Summary!$E36,Student_ICT!$D:$D,Summary!$G36) -> 0
E37: 62 | F37: Pass Duolingo | G37: ICT | H37: =COUNTIFS(Student_ICT!$I:$I,Summary!$F37,Student_ICT!$B:$B,Summary!$E37,Student_ICT!$D:$D,Summary!$G37) -> 0
E38: 62 | F38: Not Pass | G38: ICT | H38: =COUNTIFS(Student_ICT!$I:$I,Summary!$F38,Student_ICT!$B:$B,Summary!$E38,Student_ICT!$D:$D,Summary!$G38) -> 0
E39: 62 | F39: Resign | G39: ICT | H39: =COUNTIFS(Student_ICT!$I:$I,Summary!$F39,Student_ICT!$B:$B,Summary!$E39,Student_ICT!$D:$D,Summary!$G39) -> 0
E40: 62 | F40: Pass TOEIC | G40: DST | H40: =COUNTIFS(Student_ICT!$I:$I,Summary!$F40,Student_ICT!$B:$B,Summary!$E40,Student_ICT!$D:$D,Summary!$G40) -> 0
E41: 62 | F41: Pass TOEFL | G41: DST | H41: =COUNTIFS(Student_ICT!$I:$I,Summary!$F41,Student_ICT!$B:$B,Summary!$E41,Student_ICT!$D:$D,Summary!$G41) -> 0
E42: 62 | F42: Pass IELTS | G42: DST | H42: =COUNTIFS(Student_ICT!$I:$I,Summary!$F42,Student_ICT!$B:$B,Summary!$E42,Student_ICT!$D:$D,Summary!$G42) -> 0
E43: 62 | F43: Pass MUELT | G43: DST | H43: =COUNTIFS(Student_ICT!$I:$I,Summary!$F43,Student_ICT!$B:$B,Summary!$E43,Student_ICT!$D:$D,Summary!$G43) -> 0
E44: 62 | F44: Pass Duolingo | G44: DST | H44: =COUNTIFS(Student_ICT!$I:$I,Summary!$F44,Student_ICT!$B:$B,Summary!$E44,Student_ICT!$D:$D,Summary!$G44) -> 0
... E84: 64 | F84: Pass MU Intensive | G84: DST | H84: =COUNTIFS(Student_ICT!$I:$I,Summary!$F84,Student_ICT!$B:$B,Summary!$E84,Student_ICT!$D:$D,Summary!$G84) -> 0

Sheet Program
A1: Program
A2: ICT
A3: DST
